Workbook

Sheet README
A1: T26e — Junction Box: formato standard
A2: Versão | B2: v0.1 — gerado em 2026-10-23 a partir de JunctionBox_Harnes_Pinouts.xlsx (tools/migrate.py)
A4: Regras
A5: 1 | B5: Cada fio físico = 1 linha em Wires. Nunca se escreve o mesmo fio nas duas pontas.
A6: 2 | B6: Pins é calculada a partir de Wires: diz, para cada pino, que fio lá está e para onde vai. Só as colunas ref/pin/label/dir/voltage se editam à mão.
A7: 3 | B7: ref = nome do conector igual ao do RapidHarness (ex.: "AMS J11"). Pinos distinguem maiúsculas (C ≠ c nos circulares). Um conector com o mesmo nome noutro harness é a outra metade da ficha.
A8: 4 | B8: Cores em código IEC 60757 (folha Lists). Laranja (OG) ⇔ hv = Y.
A9: 5 | B9: Coluna check vazia = nada detetado. A vermelho = corrigir.
A10: 6 | B10: Um pino com vários destinos leva um splice (ref "SPL …", type SPLICE). Vários olhais no mesmo perno = type STUD.
A12: Legenda
A13: preto | B13: valor que veio do Excel original
A14: itálico laranja | B14: valor PROPOSTO na migração — confirmar e passar a preto
A15: fundo amarelo | B15: em falta — preencher
A16: cinzento | B16: fórmula — não editar
A17: linha com issue | B17: wire_id a salmão: a ligação foi corrigida ou tem dúvida — ver folha Issues
A19: Folhas
A20: Wires | B20: lista de fios (a fonte da verdade)
A21: Connectors | B21: uma linha por FICHA (metade do conector: gender M ou F), perno ou splice: P/N, crimp, HV rated, posição 3D. Um conector (ex.: LVBOX J1) = ficha macho + ficha fêmea; cada harness tem a sua, ou a outra é o header da placa.
A22: Pins | B22: pinout de cada ficha, gerado a partir de Wires
A23: Parts | B23: biblioteca de P/N (fichas, contactos, cabos) com origem de cada um
A24: Segments / Nodes | B24: topologia do RapidHarness: troços e comprimentos; xyz dos pontos de ramificação
A25: Issues | B25: problemas encontrados no Excel original — a equipa decide e fecha
A26: Notes | B26: notas da equipa que estavam nas folhas "Notas" do Excel original
A27: Lists | B27: cores e secções válidas

Sheet Wires
A1: wire_id | B1: harness | C1: net | D1: from_ref | E1: from_pin | F1: to_ref | G1: to_pin | H1: colour | I1: csa_mm2 | J1: awg | K1: hv | L1: voltage | M1: wire_pn | N1: crimp_from_pn | O1: crimp_to_pn | P1: twist_group | Q1: shield | R1: length_mm | S1: description | T1: origin | U1: issue | V1: check | W1: from_key | X1: to_key | Y1: wire_name | Z1: notes
A2: W-JBOX-001 | B2: JBOX | C2: +HV | D2: TSAL RED J1 | E2: 1 | F2: FUSE 1 | G2: ?1 | H2: OG | J2: =IF(I2="","",IFERROR(INDEX(Lists!$F$3:$F$17,MATCH(I2,Lists!$E$3:$E$17,0)),"?")) | K2: Y | L2: 600V | N2: =IF(D2="","",IFERROR(INDEX(Connectors!$J$2:$J$1000,MATCH(D2,Connectors!$A$2:$A$1000,0))&"","")) | O2: =IF(F2="","",IFERROR(INDEX(Connectors!$J$2:$J$1000,MATCH(F2,Connectors!$A$2:$A$1000,0))&"","")) | S2: Positive HV Measurement | T2: 1 ponta (folha TSAL Red) | U2: I-01 | V2: =IF(D2="","",IF(COUNTIF(Connectors!$A$2:$A$1000,D2)=0,"from_ref não existe; ","")&IF(COUNTIF(Connectors!$A$2:$A$1000,F2)=0,"to_ref não existe; ","")&IF(AND(H2<>"",COUNTIF(Lists!$A$3:$A$14,H2)=0),"cor inválida; ","")&IF(H2="","sem cor; ","")&IF((K2="Y")<>(H2="OG"),"HV e laranja não batem; ","")&IF(AND(K2="Y",OR(IFERROR(INDEX(Connectors!$F$2:$F$1000,MATCH(D2,Connectors!$A$2:$A$1000,0)),"")<>"Y",IFERROR(INDEX(Connectors!$F$2:$F$1000,MATCH(F2,Connectors!$A$2:$A$1000,0)),"")<>"Y")),"fio HV em ficha não HV rated; ","")&IF(AND(COUNTIF($W$2:$W$1000,W2)+COUNTIF($X$2:$X$1000,W2)>1,ISERROR(MATCH(IFERROR(INDEX(Connectors!$D$2:$D$1000,MATCH(D2,Connectors!$A$2:$A$1000,0)),""),{"SPLICE","STUD"},0))),"pino from com >1 fio; ","")&IF(AND(COUNTIF($W$2:$W$1000,X2)+COUNTIF($X$2:$X$1000,X2)>1,ISERROR(MATCH(IFERROR(INDEX(Connectors!$D$2:$D$1000,MATCH(F2,Connectors!$A$2:$A$1000,0)),""),{"SPLICE","STUD"},0))),"pino to com >1 fio; ","")&IF(I2="","sem secção; ","")) | W2: =IF(D2="","",D2&":"&E2&IF(EXACT(E2,UPPER(E2)),"","|lc")) | X2: =IF(F2="","",F2&":"&G2&IF(EXACT(G2,UPPER(G2)),"","|lc"))
A3: W-JBOX-002 | B3: JBOX | C3: -HV | D3: TSAL RED J1 | E3: 2 | F3: AIR- | G3: A2 | H3: OG | J3: =IF(I3="","",IFERROR(INDEX(Lists!$F$3:$F$17,MATCH(I3,Lists!$E$3:$E$17,0)),"?")) | K3: Y | L3: 0V | N3: =IF(D3="","",IFERROR(INDEX(Connectors!$J$2:$J$1000,MATCH(D3,Connectors!$A$2:$A$1000,0))&"","")) | O3: =IF(F3="","",IFERROR(INDEX(Connectors!$J$2:$J$1000,MATCH(F3,Connectors!$A$2:$A$1000,0))&"","")) | S3: Negative HV Measurement | T3: 1 ponta (folha TSAL Red) | V3: =IF(D3="","",IF(COUNTIF(Connectors!$A$2:$A$1000,D3)=0,"from_ref não existe; ","")&IF(COUNTIF(Connectors!$A$2:$A$1000,F3)=0,"to_ref não existe; ","")&IF(AND(H3<>"",COUNTIF(Lists!$A$3:$A$14,H3)=0),"cor inválida; ","")&IF(H3="","sem cor; ","")&IF((K3="Y")<>(H3="OG"),"HV e laranja não batem; ","")&IF(AND(K3="Y",OR(IFERROR(INDEX(Connectors!$F$2:$F$1000,MATCH(D3,Connectors!$A$2:$A$1000,0)),"")<>"Y",IFERROR(INDEX(Connectors!$F$2:$F$1000,MATCH(F3,Connectors!$A$2:$A$1000,0)),"")<>"Y")),"fio HV em ficha não HV rated; ","")&IF(AND(COUNTIF($W$2:$W$1000,W3)+COUNTIF($X$2:$X$1000,W3)>1,ISERROR(MATCH(IFERROR(INDEX(Connectors!$D$2:$D$1000,MATCH(D3,Connectors!$A$2:$A$1000,0)),""),{"SPLICE","STUD"},0))),"pino from com >1 fio; ","")&IF(AND(COUNTIF($W$2:$W$1000,X3)+COUNTIF($X$2:$X$1000,X3)>1,ISERROR(MATCH(IFERROR(INDEX(Connectors!$D$2:$D$1000,MATCH(F3,Connectors!$A$2:$A$1000,0)),""),{"SPLICE","STUD"},0))),"pino to com >1 fio; ","")&IF(I3="","sem secção; ","")) | W3: =IF(D3="","",D3&":"&E3&IF(EXACT(E3,UPPER(E3)),"","|lc")) | X3: =IF(F3="","",F3&":"&G3&IF(EXACT(G3,UPPER(G3)),"","|lc"))
A4: W-JBOX-003 | B4: JBOX | C4: +24V | D4: TSAL RED D2 | E4: 1 | F4: JBOX J1 | G4: ?1 | H4: RD | J4: =IF(I4="","",IFERROR(INDEX(Lists!$F$3:$F$17,MATCH(I4,Lists!$E$3:$E$17,0)),"?")) | K4: N | L4: 24V | N4: =IF(D4="","",IFERROR(INDEX(Connectors!$J$2:$J$1000,MATCH(D4,Connectors!$A$2:$A$1000,0))&"","")) | O4: =IF(F4="","",IFERROR(INDEX(Connectors!$J$2:$J$1000,MATCH(F4,Connectors!$A$2:$A$1000,0))&"","")) | S4: Board Power Supply | T4: 1 ponta (folha TSAL Red) | U4: I-01 | V4: =IF(D4="","",IF(COUNTIF(Connectors!$A$2:$A$1000,D4)=0,"from_ref não existe; ","")&IF(COUNTIF(Connectors!$A$2:$A$1000,F4)=0,"to_ref não existe; ","")&IF(AND(H4<>"",COUNTIF(Lists!$A$3:$A$14,H4)=0),"cor inválida; ","")&IF(H4="","sem cor; ","")&IF((K4="Y")<>(H4="OG"),"HV e laranja não batem; ","")&IF(AND(K4="Y",OR(IFERROR(INDEX(Connectors!$F$2:$F$1000,MATCH(D4,Connectors!$A$2:$A$1000,0)),"")<>"Y",IFERROR(INDEX(Connectors!$F$2:$F$1000,MATCH(F4,Connectors!$A$2:$A$1000,0)),"")<>"Y")),"fio HV em ficha não HV rated; ","")&IF(AND(COUNTIF($W$2:$W$1000,W4)+COUNTIF($X$2:$X$1000,W4)>1,ISERROR(MATCH(IFERROR(INDEX(Connectors!$D$2:$D$1000,MATCH(D4,Connectors!$A$2:$A$1000,0)),""),{"SPLICE","STUD"},0))),"pino from com >1 fio; ","")&IF(AND(COUNTIF($W$2:$W$1000,X4)+COUNTIF($X$2:$X$1000,X4)>1,ISERROR(MATCH(IFERROR(INDEX(Connectors!$D$2:$D$1000,MATCH(F4,Connectors!$A$2:$A$1000,0)),""),{"SPLICE","STUD"},0))),"pino to com >1 fio; ","")&IF(I4="","sem secção; ","")) | W4: =IF(D4="","",D4&":"&E4&IF(EXACT(E4,UPPER(E4)),"","|lc")) | X4: =IF(F4="","",F4&":"&G4&IF(EXACT(G4,UPPER(G4)),"","|lc"))
A5: W-JBOX-004 | B5: JBOX | C5: LED_S | D5: TSAL RED D2 | E5: 2 | F5: JBOX J1 | G5: ?2 | H5: WH | J5: =IF(I5="","",IFERROR(INDEX(Lists!$F$3:$F$17,MATCH(I5,Lists!$E$3:$E$17,0)),"?")) | K5: N | L5: 12V | N5: =IF(D5="","",IFERROR(INDEX(Connectors!$J$2:$J$1000,MATCH(D5,Connectors!$A$2:$A$1000,0))&"","")) | O5: =IF(F5="","",IFERROR(INDEX(Connectors!$J$2:$J$1000,MATCH(F5,Connectors!$A$2:$A$1000,0))&"","")) | S5: Signal for Tsal Red Led | T5: 1 ponta (folha TSAL Red) | U5: I-01 | V5: =IF(D5="","",IF(COUNTIF(Connectors!$A$2:$A$1000,D5)=0,"from_ref não existe; ","")&IF(COUNTIF(Connectors!$A$2:$A$1000,F5)=0,"to_ref não existe; ","")&IF(AND(H5<>"",COUNTIF(Lists!$A$3:$A$14,H5)=0),"cor inválida; ","")&IF(H5="","sem cor; ","")&IF((K5="Y")<>(H5="OG"),"HV e laranja não batem; ","")&IF(AND(K5="Y",OR(IFERROR(INDEX(Connectors!$F$2:$F$1000,MATCH(D5,Connectors!$A$2:$A$1000,0)),"")<>"Y",IFERROR(INDEX(Connectors!$F$2:$F$1000,MATCH(F5,Connectors!$A$2:$A$1000,0)),"")<>"Y")),"fio HV em ficha não HV rated; ","")&IF(AND(COUNTIF($W$2:$W$1000,W5)+COUNTIF($X$2:$X$1000,W5)>1,ISERROR(MATCH(IFERROR(INDEX(Connectors!$D$2:$D$1000,MATCH(D5,Connectors!$A$2:$A$1000,0)),""),{"SPLICE","STUD"},0))),"pino from com >1 fio; ","")&IF(AND(COUNTIF($W$2:$W$1000,X5)+COUNTIF($X$2:$X$1000,X5)>1,ISERROR(MATCH(IFERROR(INDEX(Connectors!$D$2:$D$1000,MATCH(F5,Connectors!$A$2:$A$1000,0)),""),{"SPLICE","STUD"},0))),"pino to com >1 fio; ","")&IF(I5="","sem secção; ","")) | W5: =IF(D5="","",D5&":"&E5&IF(EXACT(E5,UPPER(E5)),"","|lc")) | X5: =IF(F5="","",F5&":"&G5&IF(EXACT(G5,UPPER(G5)),"","|lc"))
A6: W-JBOX-005 | B6: JBOX | C6: GND | D6: TSAL RED D2 | E6: 3 | F6: GND BOARD | G6: GND | H6: BK | J6: =IF(I6="","",IFERROR(INDEX(Lists!$F$3:$F$17,MATCH(I6,Lists!$E$3:$E$17,0)),"?")) | K6: N | L6: 0V | N6: =IF(D6="","",IFERROR(INDEX(Connectors!$J$2:$J$1000,MATCH(D6,Connectors!$A$2:$A$1000,0))&"","")) | O6: =IF(F6="","",IFERROR(INDEX(Connectors!$J$2:$J$1000,MATCH(F6,Connectors!$A$2:$A$1000,0))&"","")) | S6: Power Supply Ground (Board) | T6: 1 ponta (folha TSAL Red) | V6: =IF(D6="","",IF(COUNTIF(Connectors!$A$2:$A$1000,D6)=0,"from_ref não existe; ","")&IF(COUNTIF(Connectors!$A$2:$A$1000,F6)=0,"to_ref não existe; ","")&IF(AND(H6<>"",COUNTIF(Lists!$A$3:$A$14,H6)=0),"cor inválida; ","")&IF(H6="","sem cor; ","")&IF((K6="Y")<>(H6="OG"),"HV e laranja não batem; ","")&IF(AND(K6="Y",OR(IFERROR(INDEX(Connectors!$F$2:$F$1000,MATCH(D6,Connectors!$A$2:$A$1000,0)),"")<>"Y",IFERROR(INDEX(Connectors!$F$2:$F$1000,MATCH(F6,Connectors!$A$2:$A$1000,0)),"")<>"Y")),"fio HV em ficha não HV rated; ","")&IF(AND(COUNTIF($W$2:$W$1000,W6)+COUNTIF($X$2:$X$1000,W6)>1,ISERROR(MATCH(IFERROR(INDEX(Connectors!$D$2:$D$1000,MATCH(D6,Connectors!$A$2:$A$1000,0)),""),{"SPLICE","STUD"},0))),"pino from com >1 fio; ","")&IF(AND(COUNTIF($W$2:$W$1000,X6)+COUNTIF($X$2:$X$1000,X6)>1,ISERROR(MATCH(IFERROR(INDEX(Connectors!$D$2:$D$1000,MATCH(F6,Connectors!$A$2:$A$1000,0)),""),{"SPLICE","STUD"},0))),"pino to com >1 fio; ","")&IF(I6="","sem secção; ","")) | W6: =IF(D6="","",D6&":"&E6&IF(EXACT(E6,UPPER(E6)),"","|lc")) | X6: =IF(F6="","",F6&":"&G6&IF(EXACT(G6,UPPER(G6)),"","|lc"))
A7: W-JBOX-006 | B7: JBOX | C7: GND_SHIELDS | D7: JBOX J1 | E7: f | F7: GROUND POINT | G7: GND | H7: BK | J7: =IF(I7="","",IFERROR(INDEX(Lists!$F$3:$F$17,MATCH(I7,Lists!$E$3:$E$17,0)),"?")) | K7: N | N7: =IF(D7="","",IFERROR(INDEX(Connectors!$J$2:$J$1000,MATCH(D7,Connectors!$A$2:$A$1000,0))&"","")) | O7: =IF(F7="","",IFERROR(INDEX(Connectors!$J$2:$J$1000,MATCH(F7,Connectors!$A$2:$A$1000,0))&"","")) | T7: 1 ponta (folha JBox J1) | V7: =IF(D7="","",IF(COUNTIF(Connectors!$A$2:$A$1000,D7)=0,"from_ref não existe; ","")&IF(COUNTIF(Connectors!$A$2:$A$1000,F7)=0,"to_ref não existe; ","")&IF(AND(H7<>"",COUNTIF(Lists!$A$3:$A$14,H7)=0),"cor inválida; ","")&IF(H7="","sem cor; ","")&IF((K7="Y")<>(H7="OG"),"HV e laranja não batem; ","")&IF(AND(K7="Y",OR(IFERROR(INDEX(Connectors!$F$2:$F$1000,MATCH(D7,Connectors!$A$2:$A$1000,0)),"")<>"Y",IFERROR(INDEX(Connectors!$F$2:$F$1000,MATCH(F7,Connectors!$A$2:$A$1000,0)),"")<>"Y")),"fio HV em ficha não HV rated; ","")&IF(AND(COUNTIF($W$2:$W$1000,W7)+COUNTIF($X$2:$X$1000,W7)>1,ISERROR(MATCH(IFERROR(INDEX(Connectors!$D$2:$D$1000,MATCH(D7,Connectors!$A$2:$A$1000,0)),""),{"SPLICE","STUD"},0))),"pino from com >1 fio; ","")&IF(AND(COUNTIF($W$2:$W$1000,X7)+COUNTIF($X$2:$X$1000,X7)>1,ISERROR(MATCH(IFERROR(INDEX(Connectors!$D$2:$D$1000,MATCH(F7,Connectors!$A$2:$A$1000,0)),""),{"SPLICE","STUD"},0))),"pino to com >1 fio; ","")&IF(I7="","sem secção; ","")) | W7: =IF(D7="","",D7&":"&E7&IF(EXACT(E7,UPPER(E7)),"","|lc")) | X7: =IF(F7="","",F7&":"&G7&IF(EXACT(G7,UPPER(G7)),"","|lc")) | Y7: GND SHIELD

Sheet Connectors
A1: ref | B1: device | C1: harness | D1: type | E1: n_pins | F1: hv_rated | G1: housing_pn | H1: mate_pn | I1: manufacturer | J1: contact_pn | K1: seal_pn | L1: anchor_3d | M1: x_m | N1: y_m | O1: z_m | P1: in_topology | Q1: n_wires | R1: check | S1: notes | T1: gender
A2: TSAL RED J1 | B2: TSAL | C2: JBOX | D2: CONNECTOR | E2: =COUNTIF(Pins!$A$2:$A$1000,A2) | P2: =IF(COUNTIF(Segments!$B$2:$C$1000,A2)>0,"Y","N") | Q2: =COUNTIF(Wires!$D$2:$D$1000,A2)+COUNTIF(Wires!$F$2:$F$1000,A2) | R2: =IF(A2="","",IF(D2="SPLICE","",IF(P2="N","fora da topologia; ","")&IF(G2="","sem P/N; ","")&IF(AND(G2<>"",COUNTIF(Parts!$A$2:$A$1000,G2)=0),"P/N não está em Parts; ","")&IF(M2="","sem xyz; ","")))
A3: TSAL RED D2 | B3: TSAL | C3: JBOX | D3: CONNECTOR | E3: =COUNTIF(Pins!$A$2:$A$1000,A3) | P3: =IF(COUNTIF(Segments!$B$2:$C$1000,A3)>0,"Y","N") | Q3: =COUNTIF(Wires!$D$2:$D$1000,A3)+COUNTIF(Wires!$F$2:$F$1000,A3) | R3: =IF(A3="","",IF(D3="SPLICE","",IF(P3="N","fora da topologia; ","")&IF(G3="","sem P/N; ","")&IF(AND(G3<>"",COUNTIF(Parts!$A$2:$A$1000,G3)=0),"P/N não está em Parts; ","")&IF(M3="","sem xyz; ","")))
A4: INVERTER L1 | B4: INVERTER | C4: JBOX | D4: CONNECTOR | E4: =COUNTIF(Pins!$A$2:$A$1000,A4) | P4: =IF(COUNTIF(Segments!$B$2:$C$1000,A4)>0,"Y","N") | Q4: =COUNTIF(Wires!$D$2:$D$1000,A4)+COUNTIF(Wires!$F$2:$F$1000,A4) | R4: =IF(A4="","",IF(D4="SPLICE","",IF(P4="N","fora da topologia; ","")&IF(G4="","sem P/N; ","")&IF(AND(G4<>"",COUNTIF(Parts!$A$2:$A$1000,G4)=0),"P/N não está em Parts; ","")&IF(M4="","sem xyz; ","")))
A5: INVERTER L2 | B5: INVERTER | C5: JBOX | D5: CONNECTOR | E5: =COUNTIF(Pins!$A$2:$A$1000,A5) | P5: =IF(COUNTIF(Segments!$B$2:$C$1000,A5)>0,"Y","N") | Q5: =COUNTIF(Wires!$D$2:$D$1000,A5)+COUNTIF(Wires!$F$2:$F$1000,A5) | R5: =IF(A5="","",IF(D5="SPLICE","",IF(P5="N","fora da topologia; ","")&IF(G5="","sem P/N; ","")&IF(AND(G5<>"",COUNTIF(Parts!$A$2:$A$1000,G5)=0),"P/N não está em Parts; ","")&IF(M5="","sem xyz; ","")))
A6: JBOX J1 | B6: JBOX | C6: JBOX | D6: CONNECTOR | E6: =COUNTIF(Pins!$A$2:$A$1000,A6) | G6: RTS718N32S03 | I6: Amphenol Sine RTS | J6: MS20W23F-10 | P6: =IF(COUNTIF(Segments!$B$2:$C$1000,A6)>0,"Y","N") | Q6: =COUNTIF(Wires!$D$2:$D$1000,A6)+COUNTIF(Wires!$F$2:$F$1000,A6) | R6: =IF(A6="","",IF(D6="SPLICE","",IF(P6="N","fora da topologia; ","")&IF(G6="","sem P/N; ","")&IF(AND(G6<>"",COUNTIF(Parts!$A$2:$A$1000,G6)=0),"P/N não está em Parts; ","")&IF(M6="","sem xyz; ",""))) | S6: Proposto a partir da lista da equipa (Notion · Connectors Harness): conector principal da caixa (lado da caixa, fêmea). | T6: F
A7: FUSE 1 | B7: FUSE | C7: JBOX | D7: CONNECTOR | E7: =COUNTIF(Pins!$A$2:$A$1000,A7) | P7: =IF(COUNTIF(Segments!$B$2:$C$1000,A7)>0,"Y","N") | Q7: =COUNTIF(Wires!$D$2:$D$1000,A7)+COUNTIF(Wires!$F$2:$F$1000,A7) | R7: =IF(A7="","",IF(D7="SPLICE","",IF(P7="N","fora da topologia; ","")&IF(G7="","sem P/N; ","")&IF(AND(G7<>"",COUNTIF(Parts!$A$2:$A$1000,G7)=0),"P/N não está em Parts; ","")&IF(M7="","sem xyz; ",""))) | S7: Sem folha própria — criado a partir dos destinos.
A8: AIR- | B8: AIR- | C8: JBOX | D8: CONNECTOR | E8: =COUNTIF(Pins!$A$2:$A$1000,A8) | P8: =IF(COUNTIF(Segments!$B$2:$C$1000,A8)>0,"Y","N") | Q8: =COUNTIF(Wires!$D$2:$D$1000,A8)+COUNTIF(Wires!$F$2:$F$1000,A8) | R8: =IF(A8="","",IF(D8="SPLICE","",IF(P8="N","fora da topologia; ","")&IF(G8="","sem P/N; ","")&IF(AND(G8<>"",COUNTIF(Parts!$A$2:$A$1000,G8)=0),"P/N não está em Parts; ","")&IF(M8="","sem xyz; ",""))) | S8: Sem folha própria — criado a partir dos destinos.
A9: GND BOARD | B9: GND | C9: JBOX | D9: STUD | E9: =COUNTIF(Pins!$A$2:$A$1000,A9) | P9: =IF(COUNTIF(Segments!$B$2:$C$1000,A9)>0,"Y","N") | Q9: =COUNTIF(Wires!$D$2:$D$1000,A9)+COUNTIF(Wires!$F$2:$F$1000,A9) | R9: =IF(A9="","",IF(D9="SPLICE","",IF(P9="N","fora da topologia; ","")&IF(G9="","sem P/N; ","")&IF(AND(G9<>"",COUNTIF(Parts!$A$2:$A$1000,G9)=0),"P/N não está em Parts; ","")&IF(M9="","sem xyz; ",""))) | S9: Sem folha própria — criado a partir dos destinos.
A10: GROUND POINT | B10: GROUND | C10: JBOX | D10: STUD | E10: =COUNTIF(Pins!$A$2:$A$1000,A10) | P10: =IF(COUNTIF(Segments!$B$2:$C$1000,A10)>0,"Y","N") | Q10: =COUNTIF(Wires!$D$2:$D$1000,A10)+COUNTIF(Wires!$F$2:$F$1000,A10) | R10: =IF(A10="","",IF(D10="SPLICE","",IF(P10="N","fora da topologia; ","")&IF(G10="","sem P/N; ","")&IF(AND(G10<>"",COUNTIF(Parts!$A$2:$A$1000,G10)=0),"P/N não está em Parts; ","")&IF(M10="","sem xyz; ",""))) | S10: Sem folha própria — criado a partir dos destinos.

Sheet Pins
A1: ref | B1: pin | C1: label | D1: dir | E1: voltage | F1: wire_id | G1: net | H1: connects_to | I1: colour | J1: csa_mm2 | K1: n_wires | L1: check | M1: key | N1: _row | O1: _side
A2: TSAL RED J1 | B2: 1 | C2: +HV | D2: IN | E2: 600V | F2: =IF(N2="","",INDEX(Wires!$A$2:$A$1000,N2)) | G2: =IF(N2="","",INDEX(Wires!$C$2:$C$1000,N2)) | H2: =IF(N2="","",IF(O2="from",INDEX(Wires!$F$2:$F$1000,N2)&":"&INDEX(Wires!$G$2:$G$1000,N2),INDEX(Wires!$D$2:$D$1000,N2)&":"&INDEX(Wires!$E$2:$E$1000,N2))) | I2: =IF(N2="","",INDEX(Wires!$H$2:$H$1000,N2)&"") | J2: =IF(N2="","",IF(INDEX(Wires!$I$2:$I$1000,N2)="","",INDEX(Wires!$I$2:$I$1000,N2))) | K2: =COUNTIF(Wires!$W$2:$W$1000,M2)+COUNTIF(Wires!$X$2:$X$1000,M2) | L2: =IF(AND(K2=0,C2<>"",D2<>"NC"),"pino com sinal mas sem fio; ","")&IF(AND(D2="NC",K2>0),"pino NC com fio; ","")&IF(AND(K2>1,ISERROR(MATCH(IFERROR(INDEX(Connectors!$D$2:$D$1000,MATCH(A2,Connectors!$A$2:$A$1000,0)),""),{"SPLICE","STUD"},0))),"vários fios no mesmo pino; ","") | M2: =A2&":"&B2&IF(EXACT(B2,UPPER(B2)),"","|lc") | N2: =IFERROR(MATCH(M2,Wires!$W$2:$W$1000,0),IFERROR(MATCH(M2,Wires!$X$2:$X$1000,0),"")) | O2: =IF(N2="","",IF(ISNUMBER(MATCH(M2,Wires!$W$2:$W$1000,0)),"from","to"))
A3: TSAL RED J1 | B3: 2 | C3: -HV | D3: IN | E3: 0V | F3: =IF(N3="","",INDEX(Wires!$A$2:$A$1000,N3)) | G3: =IF(N3="","",INDEX(Wires!$C$2:$C$1000,N3)) | H3: =IF(N3="","",IF(O3="from",INDEX(Wires!$F$2:$F$1000,N3)&":"&INDEX(Wires!$G$2:$G$1000,N3),INDEX(Wires!$D$2:$D$1000,N3)&":"&INDEX(Wires!$E$2:$E$1000,N3))) | I3: =IF(N3="","",INDEX(Wires!$H$2:$H$1000,N3)&"") | J3: =IF(N3="","",IF(INDEX(Wires!$I$2:$I$1000,N3)="","",INDEX(Wires!$I$2:$I$1000,N3))) | K3: =COUNTIF(Wires!$W$2:$W$1000,M3)+COUNTIF(Wires!$X$2:$X$1000,M3) | L3: =IF(AND(K3=0,C3<>"",D3<>"NC"),"pino com sinal mas sem fio; ","")&IF(AND(D3="NC",K3>0),"pino NC com fio; ","")&IF(AND(K3>1,ISERROR(MATCH(IFERROR(INDEX(Connectors!$D$2:$D$1000,MATCH(A3,Connectors!$A$2:$A$1000,0)),""),{"SPLICE","STUD"},0))),"vários fios no mesmo pino; ","") | M3: =A3&":"&B3&IF(EXACT(B3,UPPER(B3)),"","|lc") | N3: =IFERROR(MATCH(M3,Wires!$W$2:$W$1000,0),IFERROR(MATCH(M3,Wires!$X$2:$X$1000,0),"")) | O3: =IF(N3="","",IF(ISNUMBER(MATCH(M3,Wires!$W$2:$W$1000,0)),"from","to"))
A4: TSAL RED D2 | B4: 1 | C4: +24V | D4: VCC | E4: 24V | F4: =IF(N4="","",INDEX(Wires!$A$2:$A$1000,N4)) | G4: =IF(N4="","",INDEX(Wires!$C$2:$C$1000,N4)) | H4: =IF(N4="","",IF(O4="from",INDEX(Wires!$F$2:$F$1000,N4)&":"&INDEX(Wires!$G$2:$G$1000,N4),INDEX(Wires!$D$2:$D$1000,N4)&":"&INDEX(Wires!$E$2:$E$1000,N4))) | I4: =IF(N4="","",INDEX(Wires!$H$2:$H$1000,N4)&"") | J4: =IF(N4="","",IF(INDEX(Wires!$I$2:$I$1000,N4)="","",INDEX(Wires!$I$2:$I$1000,N4))) | K4: =COUNTIF(Wires!$W$2:$W$1000,M4)+COUNTIF(Wires!$X$2:$X$1000,M4) | L4: =IF(AND(K4=0,C4<>"",D4<>"NC"),"pino com sinal mas sem fio; ","")&IF(AND(D4="NC",K4>0),"pino NC com fio; ","")&IF(AND(K4>1,ISERROR(MATCH(IFERROR(INDEX(Connectors!$D$2:$D$1000,MATCH(A4,Connectors!$A$2:$A$1000,0)),""),{"SPLICE","STUD"},0))),"vários fios no mesmo pino; ","") | M4: =A4&":"&B4&IF(EXACT(B4,UPPER(B4)),"","|lc") | N4: =IFERROR(MATCH(M4,Wires!$W$2:$W$1000,0),IFERROR(MATCH(M4,Wires!$X$2:$X$1000,0),"")) | O4: =IF(N4="","",IF(ISNUMBER(MATCH(M4,Wires!$W$2:$W$1000,0)),"from","to"))
A5: TSAL RED D2 | B5: 2 | C5: Led S | D5: OUT | E5: 12V | F5: =IF(N5="","",INDEX(Wires!$A$2:$A$1000,N5)) | G5: =IF(N5="","",INDEX(Wires!$C$2:$C$1000,N5)) | H5: =IF(N5="","",IF(O5="from",INDEX(Wires!$F$2:$F$1000,N5)&":"&INDEX(Wires!$G$2:$G$1000,N5),INDEX(Wires!$D$2:$D$1000,N5)&":"&INDEX(Wires!$E$2:$E$1000,N5))) | I5: =IF(N5="","",INDEX(Wires!$H$2:$H$1000,N5)&"") | J5: =IF(N5="","",IF(INDEX(Wires!$I$2:$I$1000,N5)="","",INDEX(Wires!$I$2:$I$1000,N5))) | K5: =COUNTIF(Wires!$W$2:$W$1000,M5)+COUNTIF(Wires!$X$2:$X$1000,M5) | L5: =IF(AND(K5=0,C5<>"",D5<>"NC"),"pino com sinal mas sem fio; ","")&IF(AND(D5="NC",K5>0),"pino NC com fio; ","")&IF(AND(K5>1,ISERROR(MATCH(IFERROR(INDEX(Connectors!$D$2:$D$1000,MATCH(A5,Connectors!$A$2:$A$1000,0)),""),{"SPLICE","STUD"},0))),"vários fios no mesmo pino; ","") | M5: =A5&":"&B5&IF(EXACT(B5,UPPER(B5)),"","|lc") | N5: =IFERROR(MATCH(M5,Wires!$W$2:$W$1000,0),IFERROR(MATCH(M5,Wires!$X$2:$X$1000,0),"")) | O5: =IF(N5="","",IF(ISNUMBER(MATCH(M5,Wires!$W$2:$W$1000,0)),"from","to"))
A6: TSAL RED D2 | B6: 3 | C6: GND | D6: GND | E6: 0V | F6: =IF(N6="","",INDEX(Wires!$A$2:$A$1000,N6)) | G6: =IF(N6="","",INDEX(Wires!$C$2:$C$1000,N6)) | H6: =IF(N6="","",IF(O6="from",INDEX(Wires!$F$2:$F$1000,N6)&":"&INDEX(Wires!$G$2:$G$1000,N6),INDEX(Wires!$D$2:$D$1000,N6)&":"&INDEX(Wires!$E$2:$E$1000,N6))) | I6: =IF(N6="","",INDEX(Wires!$H$2:$H$1000,N6)&"") | J6: =IF(N6="","",IF(INDEX(Wires!$I$2:$I$1000,N6)="","",INDEX(Wires!$I$2:$I$1000,N6))) | K6: =COUNTIF(Wires!$W$2:$W$1000,M6)+COUNTIF(Wires!$X$2:$X$1000,M6) | L6: =IF(AND(K6=0,C6<>"",D6<>"NC"),"pino com sinal mas sem fio; ","")&IF(AND(D6="NC",K6>0),"pino NC com fio; ","")&IF(AND(K6>1,ISERROR(MATCH(IFERROR(INDEX(Connectors!$D$2:$D$1000,MATCH(A6,Connectors!$A$2:$A$1000,0)),""),{"SPLICE","STUD"},0))),"vários fios no mesmo pino; ","") | M6: =A6&":"&B6&IF(EXACT(B6,UPPER(B6)),"","|lc") | N6: =IFERROR(MATCH(M6,Wires!$W$2:$W$1000,0),IFERROR(MATCH(M6,Wires!$X$2:$X$1000,0),"")) | O6: =IF(N6="","",IF(ISNUMBER(MATCH(M6,Wires!$W$2:$W$1000,0)),"from","to"))
A7: INVERTER L1 | B7: 1 | F7: =IF(N7="","",INDEX(Wires!$A$2:$A$1000,N7)) | G7: =IF(N7="","",INDEX(Wires!$C$2:$C$1000,N7)) | H7: =IF(N7="","",IF(O7="from",INDEX(Wires!$F$2:$F$1000,N7)&":"&INDEX(Wires!$G$2:$G$1000,N7),INDEX(Wires!$D$2:$D$1000,N7)&":"&INDEX(Wires!$E$2:$E$1000,N7))) | I7: =IF(N7="","",INDEX(Wires!$H$2:$H$1000,N7)&"") | J7: =IF(N7="","",IF(INDEX(Wires!$I$2:$I$1000,N7)="","",INDEX(Wires!$I$2:$I$1000,N7))) | K7: =COUNTIF(Wires!$W$2:$W$1000,M7)+COUNTIF(Wires!$X$2:$X$1000,M7) | L7: =IF(AND(K7=0,C7<>"",D7<>"NC"),"pino com sinal mas sem fio; ","")&IF(AND(D7="NC",K7>0),"pino NC com fio; ","")&IF(AND(K7>1,ISERROR(MATCH(IFERROR(INDEX(Connectors!$D$2:$D$1000,MATCH(A7,Connectors!$A$2:$A$1000,0)),""),{"SPLICE","STUD"},0))),"vários fios no mesmo pino; ","") | M7: =A7&":"&B7&IF(EXACT(B7,UPPER(B7)),"","|lc") | N7: =IFERROR(MATCH(M7,Wires!$W$2:$W$1000,0),IFERROR(MATCH(M7,Wires!$X$2:$X$1000,0),"")) | O7: =IF(N7="","",IF(ISNUMBER(MATCH(M7,Wires!$W$2:$W$1000,0)),"from","to"))
A8: INVERTER L1 | B8: 2 | F8: =IF(N8="","",INDEX(Wires!$A$2:$A$1000,N8)) | G8: =IF(N8="","",INDEX(Wires!$C$2:$C$1000,N8)) | H8: =IF(N8="","",IF(O8="from",INDEX(Wires!$F$2:$F$1000,N8)&":"&INDEX(Wires!$G$2:$G$1000,N8),INDEX(Wires!$D$2:$D$1000,N8)&":"&INDEX(Wires!$E$2:$E$1000,N8))) | I8: =IF(N8="","",INDEX(Wires!$H$2:$H$1000,N8)&"") | J8: =IF(N8="","",IF(INDEX(Wires!$I$2:$I$1000,N8)="","",INDEX(Wires!$I$2:$I$1000,N8))) | K8: =COUNTIF(Wires!$W$2:$W$1000,M8)+COUNTIF(Wires!$X$2:$X$1000,M8) | L8: =IF(AND(K8=0,C8<>"",D8<>"NC"),"pino com sinal mas sem fio; ","")&IF(AND(D8="NC",K8>0),"pino NC com fio; ","")&IF(AND(K8>1,ISERROR(MATCH(IFERROR(INDEX(Connectors!$D$2:$D$1000,MATCH(A8,Connectors!$A$2:$A$1000,0)),""),{"SPLICE","STUD"},0))),"vários fios no mesmo pino; ","") | M8: =A8&":"&B8&IF(EXACT(B8,UPPER(B8)),"","|lc") | N8: =IFERROR(MATCH(M8,Wires!$W$2:$W$1000,0),IFERROR(MATCH(M8,Wires!$X$2:$X$1000,0),"")) | O8: =IF(N8="","",IF(ISNUMBER(MATCH(M8,Wires!$W$2:$W$1000,0)),"from","to"))
A9: INVERTER L1 | B9: 3 | F9: =IF(N9="","",INDEX(Wires!$A$2:$A$1000,N9)) | G9: =IF(N9="","",INDEX(Wires!$C$2:$C$1000,N9)) | H9: =IF(N9="","",IF(O9="from",INDEX(Wires!$F$2:$F$1000,N9)&":"&INDEX(Wires!$G$2:$G$1000,N9),INDEX(Wires!$D$2:$D$1000,N9)&":"&INDEX(Wires!$E$2:$E$1000,N9))) | I9: =IF(N9="","",INDEX(Wires!$H$2:$H$1000,N9)&"") | J9: =IF(N9="","",IF(INDEX(Wires!$I$2:$I$1000,N9)="","",INDEX(Wires!$I$2:$I$1000,N9))) | K9: =COUNTIF(Wires!$W$2:$W$1000,M9)+COUNTIF(Wires!$X$2:$X$1000,M9) | L9: =IF(AND(K9=0,C9<>"",D9<>"NC"),"pino com sinal mas sem fio; ","")&IF(AND(D9="NC",K9>0),"pino NC com fio; ","")&IF(AND(K9>1,ISERROR(MATCH(IFERROR(INDEX(Connectors!$D$2:$D$1000,MATCH(A9,Connectors!$A$2:$A$1000,0)),""),{"SPLICE","STUD"},0))),"vários fios no mesmo pino; ","") | M9: =A9&":"&B9&IF(EXACT(B9,UPPER(B9)),"","|lc") | N9: =IFERROR(MATCH(M9,Wires!$W$2:$W$1000,0),IFERROR(MATCH(M9,Wires!$X$2:$X$1000,0),"")) | O9: =IF(N9="","",IF(ISNUMBER(MATCH(M9,Wires!$W$2:$W$1000,0)),"from","to"))
A10: INVERTER L1 | B10: 4 | F10: =IF(N10="","",INDEX(Wires!$A$2:$A$1000,N10)) | G10: =IF(N10="","",INDEX(Wires!$C$2:$C$1000,N10)) | H10: =IF(N10="","",IF(O10="from",INDEX(Wires!$F$2:$F$1000,N10)&":"&INDEX(Wires!$G$2:$G$1000,N10),INDEX(Wires!$D$2:$D$1000,N10)&":"&INDEX(Wires!$E$2:$E$1000,N10))) | I10: =IF(N10="","",INDEX(Wires!$H$2:$H$1000,N10)&"") | J10: =IF(N10="","",IF(INDEX(Wires!$I$2:$I$1000,N10)="","",INDEX(Wires!$I$2:$I$1000,N10))) | K10: =COUNTIF(Wires!$W$2:$W$1000,M10)+COUNTIF(Wires!$X$2:$X$1000,M10) | L10: =IF(AND(K10=0,C10<>"",D10<>"NC"),"pino com sinal mas sem fio; ","")&IF(AND(D10="NC",K10>0),"pino NC com fio; ","")&IF(AND(K10>1,ISERROR(MATCH(IFERROR(INDEX(Connectors!$D$2:$D$1000,MATCH(A10,Connectors!$A$2:$A$1000,0)),""),{"SPLICE","STUD"},0))),"vários fios no mesmo pino; ","") | M10: =A10&":"&B10&IF(EXACT(B10,UPPER(B10)),"","|lc") | N10: =IFERROR(MATCH(M10,Wires!$W$2:$W$1000,0),IFERROR(MATCH(M10,Wires!$X$2:$X$1000,0),"")) | O10: =IF(N10="","",IF(ISNUMBER(MATCH(M10,Wires!$W$2:$W$1000,0)),"from","to"))
A11: INVERTER L1 | B11: 5 | F11: =IF(N11="","",INDEX(Wires!$A$2:$A$1000,N11)) | G11: =IF(N11="","",INDEX(Wires!$C$2:$C$1000,N11)) | H11: =IF(N11="","",IF(O11="from",INDEX(Wires!$F$2:$F$1000,N11)&":"&INDEX(Wires!$G$2:$G$1000,N11),INDEX(Wires!$D$2:$D$1000,N11)&":"&INDEX(Wires!$E$2:$E$1000,N11))) | I11: =IF(N11="","",INDEX(Wires!$H$2:$H$1000,N11)&"") | J11: =IF(N11="","",IF(INDEX(Wires!$I$2:$I$1000,N11)="","",INDEX(Wires!$I$2:$I$1000,N11))) | K11: =COUNTIF(Wires!$W$2:$W$1000,M11)+COUNTIF(Wires!$X$2:$X$1000,M11) | L11: =IF(AND(K11=0,C11<>"",D11<>"NC"),"pino com sinal mas sem fio; ","")&IF(AND(D11="NC",K11>0),"pino NC com fio; ","")&IF(AND(K11>1,ISERROR(MATCH(IFERROR(INDEX(Connectors!$D$2:$D$1000,MATCH(A11,Connectors!$A$2:$A$1000,0)),""),{"SPLICE","STUD"},0))),"vários fios no mesmo pino; ","") | M11: =A11&":"&B11&IF(EXACT(B11,UPPER(B11)),"","|lc") | N11: =IFERROR(MATCH(M11,Wires!$W$2:$W$1000,0),IFERROR(MATCH(M11,Wires!$X$2:$X$1000,0),"")) | O11: =IF(N11="","",IF(ISNUMBER(MATCH(M11,Wires!$W$2:$W$1000,0)),"from","to"))
A12: INVERTER L1 | B12: 6 | F12: =IF(N12="","",INDEX(Wires!$A$2:$A$1000,N12)) | G12: =IF(N12="","",INDEX(Wires!$C$2:$C$1000,N12)) | H12: =IF(N12="","",IF(O12="from",INDEX(Wires!$F$2:$F$1000,N12)&":"&INDEX(Wires!$G$2:$G$1000,N12),INDEX(Wires!$D$2:$D$1000,N12)&":"&INDEX(Wires!$E$2:$E$1000,N12))) | I12: =IF(N12="","",INDEX(Wires!$H$2:$H$1000,N12)&"") | J12: =IF(N12="","",IF(INDEX(Wires!$I$2:$I$1000,N12)="","",INDEX(Wires!$I$2:$I$1000,N12))) | K12: =COUNTIF(Wires!$W$2:$W$1000,M12)+COUNTIF(Wires!$X$2:$X$1000,M12) | L12: =IF(AND(K12=0,C12<>"",D12<>"NC"),"pino com sinal mas sem fio; ","")&IF(AND(D12="NC",K12>0),"pino NC com fio; ","")&IF(AND(K12>1,ISERROR(MATCH(IFERROR(INDEX(Connectors!$D$2:$D$1000,MATCH(A12,Connectors!$A$2:$A$1000,0)),""),{"SPLICE","STUD"},0))),"vários fios no mesmo pino; ","") | M12: =A12&":"&B12&IF(EXACT(B12,UPPER(B12)),"","|lc") | N12: =IFERROR(MATCH(M12,Wires!$W$2:$W$1000,0),IFERROR(MATCH(M12,Wires!$X$2:$X$1000,0),"")) | O12: =IF(N12="","",IF(ISNUMBER(MATCH(M12,Wires!$W$2:$W$1000,0)),"from","to"))
A13: INVERTER L1 | B13: 7 | F13: =IF(N13="","",INDEX(Wires!$A$2:$A$1000,N13)) | G13: =IF(N13="","",INDEX(Wires!$C$2:$C$1000,N13)) | H13: =IF(N13="","",IF(O13="from",INDEX(Wires!$F$2:$F$1000,N13)&":"&INDEX(Wires!$G$2:$G$1000,N13),INDEX(Wires!$D$2:$D$1000,N13)&":"&INDEX(Wires!$E$2:$E$1000,N13))) | I13: =IF(N13="","",INDEX(Wires!$H$2:$H$1000,N13)&"") | J13: =IF(N13="","",IF(INDEX(Wires!$I$2:$I$1000,N13)="","",INDEX(Wires!$I$2:$I$1000,N13))) | K13: =COUNTIF(Wires!$W$2:$W$1000,M13)+COUNTIF(Wires!$X$2:$X$1000,M13) | L13: =IF(AND(K13=0,C13<>"",D13<>"NC"),"pino com sinal mas sem fio; ","")&IF(AND(D13="NC",K13>0),"pino NC com fio; ","")&IF(AND(K13>1,ISERROR(MATCH(IFERROR(INDEX(Connectors!$D$2:$D$1000,MATCH(A13,Connectors!$A$2:$A$1000,0)),""),{"SPLICE","STUD"},0))),"vários fios no mesmo pino; ","") | M13: =A13&":"&B13&IF(EXACT(B13,UPPER(B13)),"","|lc") | N13: =IFERROR(MATCH(M13,Wires!$W$2:$W$1000,0),IFERROR(MATCH(M13,Wires!$X$2:$X$1000,0),"")) | O13: =IF(N13="","",IF(ISNUMBER(MATCH(M13,Wires!$W$2:$W$1000,0)),"from","to"))
A14: INVERTER L1 | B14: 8 | F14: =IF(N14="","",INDEX(Wires!$A$2:$A$1000,N14)) | G14: =IF(N14="","",INDEX(Wires!$C$2:$C$1000,N14)) | H14: =IF(N14="","",IF(O14="from",INDEX(Wires!$F$2:$F$1000,N14)&":"&INDEX(Wires!$G$2:$G$1000,N14),INDEX(Wires!$D$2:$D$1000,N14)&":"&INDEX(Wires!$E$2:$E$1000,N14))) | I14: =IF(N14="","",INDEX(Wires!$H$2:$H$1000,N14)&"") | J14: =IF(N14="","",IF(INDEX(Wires!$I$2:$I$1000,N14)="","",INDEX(Wires!$I$2:$I$1000,N14))) | K14: =COUNTIF(Wires!$W$2:$W$1000,M14)+COUNTIF(Wires!$X$2:$X$1000,M14) | L14: =IF(AND(K14=0,C14<>"",D14<>"NC"),"pino com sinal mas sem fio; ","")&IF(AND(D14="NC",K14>0),"pino NC com fio; ","")&IF(AND(K14>1,ISERROR(MATCH(IFERROR(INDEX(Connectors!$D$2:$D$1000,MATCH(A14,Connectors!$A$2:$A$1000,0)),""),{"SPLICE","STUD"},0))),"vários fios no mesmo pino; ","") | M14: =A14&":"&B14&IF(EXACT(B14,UPPER(B14)),"","|lc") | N14: =IFERROR(MATCH(M14,Wires!$W$2:$W$1000,0),IFERROR(MATCH(M14,Wires!$X$2:$X$1000,0),"")) | O14: =IF(N14="","",IF(ISNUMBER(MATCH(M14,Wires!$W$2:$W$1000,0)),"from","to"))
A15: INVERTER L1 | B15: 9 | F15: =IF(N15="","",INDEX(Wires!$A$2:$A$1000,N15)) | G15: =IF(N15="","",INDEX(Wires!$C$2:$C$1000,N15)) | H15: =IF(N15="","",IF(O15="from",INDEX(Wires!$F$2:$F$1000,N15)&":"&INDEX(Wires!$G$2:$G$1000,N15),INDEX(Wires!$D$2:$D$1000,N15)&":"&INDEX(Wires!$E$2:$E$1000,N15))) | I15: =IF(N15="","",INDEX(Wires!$H$2:$H$1000,N15)&"") | J15: =IF(N15="","",IF(INDEX(Wires!$I$2:$I$1000,N15)="","",INDEX(Wires!$I$2:$I$1000,N15))) | K15: =COUNTIF(Wires!$W$2:$W$1000,M15)+COUNTIF(Wires!$X$2:$X$1000,M15) | L15: =IF(AND(K15=0,C15<>"",D15<>"NC"),"pino com sinal mas sem fio; ","")&IF(AND(D15="NC",K15>0),"pino NC com fio; ","")&IF(AND(K15>1,ISERROR(MATCH(IFERROR(INDEX(Connectors!$D$2:$D$1000,MATCH(A15,Connectors!$A$2:$A$1000,0)),""),{"SPLICE","STUD"},0))),"vários fios no mesmo pino; ","") | M15: =A15&":"&B15&IF(EXACT(B15,UPPER(B15)),"","|lc") | N15: =IFERROR(MATCH(M15,Wires!$W$2:$W$1000,0),IFERROR(MATCH(M15,Wires!$X$2:$X$1000,0),"")) | O15: =IF(N15="","",IF(ISNUMBER(MATCH(M15,Wires!$W$2:$W$1000,0)),"from","to"))
A16: INVERTER L1 | B16: 10 | F16: =IF(N16="","",INDEX(Wires!$A$2:$A$1000,N16)) | G16: =IF(N16="","",INDEX(Wires!$C$2:$C$1000,N16)) | H16: =IF(N16="","",IF(O16="from",INDEX(Wires!$F$2:$F$1000,N16)&":"&INDEX(Wires!$G$2:$G$1000,N16),INDEX(Wires!$D$2:$D$1000,N16)&":"&INDEX(Wires!$E$2:$E$1000,N16))) | I16: =IF(N16="","",INDEX(Wires!$H$2:$H$1000,N16)&"") | J16: =IF(N16="","",IF(INDEX(Wires!$I$2:$I$1000,N16)="","",INDEX(Wires!$I$2:$I$1000,N16))) | K16: =COUNTIF(Wires!$W$2:$W$1000,M16)+COUNTIF(Wires!$X$2:$X$1000,M16) | L16: =IF(AND(K16=0,C16<>"",D16<>"NC"),"pino com sinal mas sem fio; ","")&IF(AND(D16="NC",K16>0),"pino NC com fio; ","")&IF(AND(K16>1,ISERROR(MATCH(IFERROR(INDEX(Connectors!$D$2:$D$1000,MATCH(A16,Connectors!$A$2:$A$1000,0)),""),{"SPLICE","STUD"},0))),"vários fios no mesmo pino; ","") | M16: =A16&":"&B16&IF(EXACT(B16,UPPER(B16)),"","|lc") | N16: =IFERROR(MATCH(M16,Wires!$W$2:$W$1000,0),IFERROR(MATCH(M16,Wires!$X$2:$X$1000,0),"")) | O16: =IF(N16="","",IF(ISNUMBER(MATCH(M16,Wires!$W$2:$W$1000,0)),"from","to"))
A17: INVERTER L1 | B17: 11 | F17: =IF(N17="","",INDEX(Wires!$A$2:$A$1000,N17)) | G17: =IF(N17="","",INDEX(Wires!$C$2:$C$1000,N17)) | H17: =IF(N17="","",IF(O17="from",INDEX(Wires!$F$2:$F$1000,N17)&":"&INDEX(Wires!$G$2:$G$1000,N17),INDEX(Wires!$D$2:$D$1000,N17)&":"&INDEX(Wires!$E$2:$E$1000,N17))) | I17: =IF(N17="","",INDEX(Wires!$H$2:$H$1000,N17)&"") | J17: =IF(N17="","",IF(INDEX(Wires!$I$2:$I$1000,N17)="","",INDEX(Wires!$I$2:$I$1000,N17))) | K17: =COUNTIF(Wires!$W$2:$W$1000,M17)+COUNTIF(Wires!$X$2:$X$1000,M17) | L17: =IF(AND(K17=0,C17<>"",D17<>"NC"),"pino com sinal mas sem fio; ","")&IF(AND(D17="NC",K17>0),"pino NC com fio; ","")&IF(AND(K17>1,ISERROR(MATCH(IFERROR(INDEX(Connectors!$D$2:$D$1000,MATCH(A17,Connectors!$A$2:$A$1000,0)),""),{"SPLICE","STUD"},0))),"vários fios no mesmo pino; ","") | M17: =A17&":"&B17&IF(EXACT(B17,UPPER(B17)),"","|lc") | N17: =IFERROR(MATCH(M17,Wires!$W$2:$W$1000,0),IFERROR(MATCH(M17,Wires!$X$2:$X$1000,0),"")) | O17: =IF(N17="","",IF(ISNUMBER(MATCH(M17,Wires!$W$2:$W$1000,0)),"from","to"))
A18: INVERTER L1 | B18: 12 | F18: =IF(N18="","",INDEX(Wires!$A$2:$A$1000,N18)) | G18: =IF(N18="","",INDEX(Wires!$C$2:$C$1000,N18)) | H18: =IF(N18="","",IF(O18="from",INDEX(Wires!$F$2:$F$1000,N18)&":"&INDEX(Wires!$G$2:$G$1000,N18),INDEX(Wires!$D$2:$D$1000,N18)&":"&INDEX(Wires!$E$2:$E$1000,N18))) | I18: =IF(N18="","",INDEX(Wires!$H$2:$H$1000,N18)&"") | J18: =IF(N18="","",IF(INDEX(Wires!$I$2:$I$1000,N18)="","",INDEX(Wires!$I$2:$I$1000,N18))) | K18: =COUNTIF(Wires!$W$2:$W$1000,M18)+COUNTIF(Wires!$X$2:$X$1000,M18) | L18: =IF(AND(K18=0,C18<>"",D18<>"NC"),"pino com sinal mas sem fio; ","")&IF(AND(D18="NC",K18>0),"pino NC com fio; ","")&IF(AND(K18>1,ISERROR(MATCH(IFERROR(INDEX(Connectors!$D$2:$D$1000,MATCH(A18,Connectors!$A$2:$A$1000,0)),""),{"SPLICE","STUD"},0))),"vários fios no mesmo pino; ","") | M18: =A18&":"&B18&IF(EXACT(B18,UPPER(B18)),"","|lc") | N18: =IFERROR(MATCH(M18,Wires!$W$2:$W$1000,0),IFERROR(MATCH(M18,Wires!$X$2:$X$1000,0),"")) | O18: =IF(N18="","",IF(ISNUMBER(MATCH(M18,Wires!$W$2:$W$1000,0)),"from","to"))
... A30: INVERTER L2 | B30: 12 | F30: =IF(N30="","",INDEX(Wires!$A$2:$A$1000,N30)) | G30: =IF(N30="","",INDEX(Wires!$C$2:$C$1000,N30)) | H30: =IF(N30="","",IF(O30="from",INDEX(Wires!$F$2:$F$1000,N30)&":"&INDEX(Wires!$G$2:$G$1000,N30),INDEX(Wires!$D$2:$D$1000,N30)&":"&INDEX(Wires!$E$2:$E$1000,N30))) | I30: =IF(N30="","",INDEX(Wires!$H$2:$H$1000,N30)&"") | J30: =IF(N30="","",IF(INDEX(Wires!$I$2:$I$1000,N30)="","",INDEX(Wires!$I$2:$I$1000,N30))) | K30: =COUNTIF(Wires!$W$2:$W$1000,M30)+COUNTIF(Wires!$X$2:$X$1000,M30) | L30: =IF(AND(K30=0,C30<>"",D30<>"NC"),"pino com sinal mas sem fio; ","")&IF(AND(D30="NC",K30>0),"pino NC com fio; ","")&IF(AND(K30>1,ISERROR(MATCH(IFERROR(INDEX(Connectors!$D$2:$D$1000,MATCH(A30,Connectors!$A$2:$A$1000,0)),""),{"SPLICE","STUD"},0))),"vários fios no mesmo pino; ","") | M30: =A30&":"&B30&IF(EXACT(B30,UPPER(B30)),"","|lc") | N30: =IFERROR(MATCH(M30,Wires!$W$2:$W$1000,0),IFERROR(MATCH(M30,Wires!$X$2:$X$1000,0),"")) | O30: =IF(N30="","",IF(ISNUMBER(MATCH(M30,Wires!$W$2:$W$1000,0)),"from","to"))
A31: JBOX J1 | B31: A | C31: 24V | F31: =IF(N31="","",INDEX(Wires!$A$2:$A$1000,N31)) | G31: =IF(N31="","",INDEX(Wires!$C$2:$C$1000,N31)) | H31: =IF(N31="","",IF(O31="from",INDEX(Wires!$F$2:$F$1000,N31)&":"&INDEX(Wires!$G$2:$G$1000,N31),INDEX(Wires!$D$2:$D$1000,N31)&":"&INDEX(Wires!$E$2:$E$1000,N31))) | I31: =IF(N31="","",INDEX(Wires!$H$2:$H$1000,N31)&"") | J31: =IF(N31="","",IF(INDEX(Wires!$I$2:$I$1000,N31)="","",INDEX(Wires!$I$2:$I$1000,N31))) | K31: =COUNTIF(Wires!$W$2:$W$1000,M31)+COUNTIF(Wires!$X$2:$X$1000,M31) | L31: =IF(AND(K31=0,C31<>"",D31<>"NC"),"pino com sinal mas sem fio; ","")&IF(AND(D31="NC",K31>0),"pino NC com fio; ","")&IF(AND(K31>1,ISERROR(MATCH(IFERROR(INDEX(Connectors!$D$2:$D$1000,MATCH(A31,Connectors!$A$2:$A$1000,0)),""),{"SPLICE","STUD"},0))),"vários fios no mesmo pino; ","") | M31: =A31&":"&B31&IF(EXACT(B31,UPPER(B31)),"","|lc") | N31: =IFERROR(MATCH(M31,Wires!$W$2:$W$1000,0),IFERROR(MATCH(M31,Wires!$X$2:$X$1000,0),"")) | O31: =IF(N31="","",IF(ISNUMBER(MATCH(M31,Wires!$W$2:$W$1000,0)),"from","to"))
A32: JBOX J1 | B32: B | C32: GND | F32: =IF(N32="","",INDEX(Wires!$A$2:$A$1000,N32)) | G32: =IF(N32="","",INDEX(Wires!$C$2:$C$1000,N32)) | H32: =IF(N32="","",IF(O32="from",INDEX(Wires!$F$2:$F$1000,N32)&":"&INDEX(Wires!$G$2:$G$1000,N32),INDEX(Wires!$D$2:$D$1000,N32)&":"&INDEX(Wires!$E$2:$E$1000,N32))) | I32: =IF(N32="","",INDEX(Wires!$H$2:$H$1000,N32)&"") | J32: =IF(N32="","",IF(INDEX(Wires!$I$2:$I$1000,N32)="","",INDEX(Wires!$I$2:$I$1000,N32))) | K32: =COUNTIF(Wires!$W$2:$W$1000,M32)+COUNTIF(Wires!$X$2:$X$1000,M32) | L32: =IF(AND(K32=0,C32<>"",D32<>"NC"),"pino com sinal mas sem fio; ","")&IF(AND(D32="NC",K32>0),"pino NC com fio; ","")&IF(AND(K32>1,ISERROR(MATCH(IFERROR(INDEX(Connectors!$D$2:$D$1000,MATCH(A32,Connectors!$A$2:$A$1000,0)),""),{"SPLICE","STUD"},0))),"vários fios no mesmo pino; ","") | M32: =A32&":"&B32&IF(EXACT(B32,UPPER(B32)),"","|lc") | N32: =IFERROR(MATCH(M32,Wires!$W$2:$W$1000,0),IFERROR(MATCH(M32,Wires!$X$2:$X$1000,0),"")) | O32: =IF(N32="","",IF(ISNUMBER(MATCH(M32,Wires!$W$2:$W$1000,0)),"from","to"))
A33: JBOX J1 | B33: C | C33: Discharge GND | F33: =IF(N33="","",INDEX(Wires!$A$2:$A$1000,N33)) | G33: =IF(N33="","",INDEX(Wires!$C$2:$C$1000,N33)) | H33: =IF(N33="","",IF(O33="from",INDEX(Wires!$F$2:$F$1000,N33)&":"&INDEX(Wires!$G$2:$G$1000,N33),INDEX(Wires!$D$2:$D$1000,N33)&":"&INDEX(Wires!$E$2:$E$1000,N33))) | I33: =IF(N33="","",INDEX(Wires!$H$2:$H$1000,N33)&"") | J33: =IF(N33="","",IF(INDEX(Wires!$I$2:$I$1000,N33)="","",INDEX(Wires!$I$2:$I$1000,N33))) | K33: =COUNTIF(Wires!$W$2:$W$1000,M33)+COUNTIF(Wires!$X$2:$X$1000,M33) | L33: =IF(AND(K33=0,C33<>"",D33<>"NC"),"pino com sinal mas sem fio; ","")&IF(AND(D33="NC",K33>0),"pino NC com fio; ","")&IF(AND(K33>1,ISERROR(MATCH(IFERROR(INDEX(Connectors!$D$2:$D$1000,MATCH(A33,Connectors!$A$2:$A$1000,0)),""),{"SPLICE","STUD"},0))),"vários fios no mesmo pino; ","") | M33: =A33&":"&B33&IF(EXACT(B33,UPPER(B33)),"","|lc") | N33: =IFERROR(MATCH(M33,Wires!$W$2:$W$1000,0),IFERROR(MATCH(M33,Wires!$X$2:$X$1000,0),"")) | O33: =IF(N33="","",IF(ISNUMBER(MATCH(M33,Wires!$W$2:$W$1000,0)),"from","to"))
A34: JBOX J1 | B34: D | C34: Shutdown Circuit (supply contactors) | F34: =IF(N34="","",INDEX(Wires!$A$2:$A$1000,N34)) | G34: =IF(N34="","",INDEX(Wires!$C$2:$C$1000,N34)) | H34: =IF(N34="","",IF(O34="from",INDEX(Wires!$F$2:$F$1000,N34)&":"&INDEX(Wires!$G$2:$G$1000,N34),INDEX(Wires!$D$2:$D$1000,N34)&":"&INDEX(Wires!$E$2:$E$1000,N34))) | I34: =IF(N34="","",INDEX(Wires!$H$2:$H$1000,N34)&"") | J34: =IF(N34="","",IF(INDEX(Wires!$I$2:$I$1000,N34)="","",INDEX(Wires!$I$2:$I$1000,N34))) | K34: =COUNTIF(Wires!$W$2:$W$1000,M34)+COUNTIF(Wires!$X$2:$X$1000,M34) | L34: =IF(AND(K34=0,C34<>"",D34<>"NC"),"pino com sinal mas sem fio; ","")&IF(AND(D34="NC",K34>0),"pino NC com fio; ","")&IF(AND(K34>1,ISERROR(MATCH(IFERROR(INDEX(Connectors!$D$2:$D$1000,MATCH(A34,Connectors!$A$2:$A$1000,0)),""),{"SPLICE","STUD"},0))),"vários fios no mesmo pino; ","") | M34: =A34&":"&B34&IF(EXACT(B34,UPPER(B34)),"","|lc") | N34: =IFERROR(MATCH(M34,Wires!$W$2:$W$1000,0),IFERROR(MATCH(M34,Wires!$X$2:$X$1000,0),"")) | O34: =IF(N34="","",IF(ISNUMBER(MATCH(M34,Wires!$W$2:$W$1000,0)),"from","to"))
A35: JBOX J1 | B35: E | C35: TSAL Red 1 | F35: =IF(N35="","",INDEX(Wires!$A$2:$A$1000,N35)) | G35: =IF(N35="","",INDEX(Wires!$C$2:$C$1000,N35)) | H35: =IF(N35="","",IF(O35="from",INDEX(Wires!$F$2:$F$1000,N35)&":"&INDEX(Wires!$G$2:$G$1000,N35),INDEX(Wires!$D$2:$D$1000,N35)&":"&INDEX(Wires!$E$2:$E$1000,N35))) | I35: =IF(N35="","",INDEX(Wires!$H$2:$H$1000,N35)&"") | J35: =IF(N35="","",IF(INDEX(Wires!$I$2:$I$1000,N35)="","",INDEX(Wires!$I$2:$I$1000,N35))) | K35: =COUNTIF(Wires!$W$2:$W$1000,M35)+COUNTIF(Wires!$X$2:$X$1000,M35) | L35: =IF(AND(K35=0,C35<>"",D35<>"NC"),"pino com sinal mas sem fio; ","")&IF(AND(D35="NC",K35>0),"pino NC com fio; ","")&IF(AND(K35>1,ISERROR(MATCH(IFERROR(INDEX(Connectors!$D$2:$D$1000,MATCH(A35,Connectors!$A$2:$A$1000,0)),""),{"SPLICE","STUD"},0))),"vários fios no mesmo pino; ","") | M35: =A35&":"&B35&IF(EXACT(B35,UPPER(B35)),"","|lc") | N35: =IFERROR(MATCH(M35,Wires!$W$2:$W$1000,0),IFERROR(MATCH(M35,Wires!$X$2:$X$1000,0),"")) | O35: =IF(N35="","",IF(ISNUMBER(MATCH(M35,Wires!$W$2:$W$1000,0)),"from","to"))
A36: JBOX J1 | B36: F | C36: TSAL Red 2 | F36: =IF(N36="","",INDEX(Wires!$A$2:$A$1000,N36)) | G36: =IF(N36="","",INDEX(Wires!$C$2:$C$1000,N36)) | H36: =IF(N36="","",IF(O36="from",INDEX(Wires!$F$2:$F$1000,N36)&":"&INDEX(Wires!$G$2:$G$1000,N36),INDEX(Wires!$D$2:$D$1000,N36)&":"&INDEX(Wires!$E$2:$E$1000,N36))) | I36: =IF(N36="","",INDEX(Wires!$H$2:$H$1000,N36)&"") | J36: =IF(N36="","",IF(INDEX(Wires!$I$2:$I$1000,N36)="","",INDEX(Wires!$I$2:$I$1000,N36))) | K36: =COUNTIF(Wires!$W$2:$W$1000,M36)+COUNTIF(Wires!$X$2:$X$1000,M36) | L36: =IF(AND(K36=0,C36<>"",D36<>"NC"),"pino com sinal mas sem fio; ","")&IF(AND(D36="NC",K36>0),"pino NC com fio; ","")&IF(AND(K36>1,ISERROR(MATCH(IFERROR(INDEX(Connectors!$D$2:$D$1000,MATCH(A36,Connectors!$A$2:$A$1000,0)),""),{"SPLICE","STUD"},0))),"vários fios no mesmo pino; ","") | M36: =A36&":"&B36&IF(EXACT(B36,UPPER(B36)),"","|lc") | N36: =IFERROR(MATCH(M36,Wires!$W$2:$W$1000,0),IFERROR(MATCH(M36,Wires!$X$2:$X$1000,0),"")) | O36: =IF(N36="","",IF(ISNUMBER(MATCH(M36,Wires!$W$2:$W$1000,0)),"from","to"))
A37: JBOX J1 | B37: G | C37: 24V Sensor Corrente BSPD | F37: =IF(N37="","",INDEX(Wires!$A$2:$A$1000,N37)) | G37: =IF(N37="","",INDEX(Wires!$C$2:$C$1000,N37)) | H37: =IF(N37="","",IF(O37="from",INDEX(Wires!$F$2:$F$1000,N37)&":"&INDEX(Wires!$G$2:$G$1000,N37),INDEX(Wires!$D$2:$D$1000,N37)&":"&INDEX(Wires!$E$2:$E$1000,N37))) | I37: =IF(N37="","",INDEX(Wires!$H$2:$H$1000,N37)&"") | J37: =IF(N37="","",IF(INDEX(Wires!$I$2:$I$1000,N37)="","",INDEX(Wires!$I$2:$I$1000,N37))) | K37: =COUNTIF(Wires!$W$2:$W$1000,M37)+COUNTIF(Wires!$X$2:$X$1000,M37) | L37: =IF(AND(K37=0,C37<>"",D37<>"NC"),"pino com sinal mas sem fio; ","")&IF(AND(D37="NC",K37>0),"pino NC com fio; ","")&IF(AND(K37>1,ISERROR(MATCH(IFERROR(INDEX(Connectors!$D$2:$D$1000,MATCH(A37,Connectors!$A$2:$A$1000,0)),""),{"SPLICE","STUD"},0))),"vários fios no mesmo pino; ","") | M37: =A37&":"&B37&IF(EXACT(B37,UPPER(B37)),"","|lc") | N37: =IFERROR(MATCH(M37,Wires!$W$2:$W$1000,0),IFERROR(MATCH(M37,Wires!$X$2:$X$1000,0),"")) | O37: =IF(N37="","",IF(ISNUMBER(MATCH(M37,Wires!$W$2:$W$1000,0)),"from","to"))
A38: JBOX J1 | B38: H | C38: Sinal Sensor Corrente BSPD | F38: =IF(N38="","",INDEX(Wires!$A$2:$A$1000,N38)) | G38: =IF(N38="","",INDEX(Wires!$C$2:$C$1000,N38)) | H38: =IF(N38="","",IF(O38="from",INDEX(Wires!$F$2:$F$1000,N38)&":"&INDEX(Wires!$G$2:$G$1000,N38),INDEX(Wires!$D$2:$D$1000,N38)&":"&INDEX(Wires!$E$2:$E$1000,N38))) | I38: =IF(N38="","",INDEX(Wires!$H$2:$H$1000,N38)&"") | J38: =IF(N38="","",IF(INDEX(Wires!$I$2:$I$1000,N38)="","",INDEX(Wires!$I$2:$I$1000,N38))) | K38: =COUNTIF(Wires!$W$2:$W$1000,M38)+COUNTIF(Wires!$X$2:$X$1000,M38) | L38: =IF(AND(K38=0,C38<>"",D38<>"NC"),"pino com sinal mas sem fio; ","")&IF(AND(D38="NC",K38>0),"pino NC com fio; ","")&IF(AND(K38>1,ISERROR(MATCH(IFERROR(INDEX(Connectors!$D$2:$D$1000,MATCH(A38,Connectors!$A$2:$A$1000,0)),""),{"SPLICE","STUD"},0))),"vários fios no mesmo pino; ","") | M38: =A38&":"&B38&IF(EXACT(B38,UPPER(B38)),"","|lc") | N38: =IFERROR(MATCH(M38,Wires!$W$2:$W$1000,0),IFERROR(MATCH(M38,Wires!$X$2:$X$1000,0),"")) | O38: =IF(N38="","",IF(ISNUMBER(MATCH(M38,Wires!$W$2:$W$1000,0)),"from","to"))
A39: JBOX J1 | B39: J | C39: GND Sensor Corrente BSPD | F39: =IF(N39="","",INDEX(Wires!$A$2:$A$1000,N39)) | G39: =IF(N39="","",INDEX(Wires!$C$2:$C$1000,N39)) | H39: =IF(N39="","",IF(O39="from",INDEX(Wires!$F$2:$F$1000,N39)&":"&INDEX(Wires!$G$2:$G$1000,N39),INDEX(Wires!$D$2:$D$1000,N39)&":"&INDEX(Wires!$E$2:$E$1000,N39))) | I39: =IF(N39="","",INDEX(Wires!$H$2:$H$1000,N39)&"") | J39: =IF(N39="","",IF(INDEX(Wires!$I$2:$I$1000,N39)="","",INDEX(Wires!$I$2:$I$1000,N39))) | K39: =COUNTIF(Wires!$W$2:$W$1000,M39)+COUNTIF(Wires!$X$2:$X$1000,M39) | L39: =IF(AND(K39=0,C39<>"",D39<>"NC"),"pino com sinal mas sem fio; ","")&IF(AND(D39="NC",K39>0),"pino NC com fio; ","")&IF(AND(K39>1,ISERROR(MATCH(IFERROR(INDEX(Connectors!$D$2:$D$1000,MATCH(A39,Connectors!$A$2:$A$1000,0)),""),{"SPLICE","STUD"},0))),"vários fios no mesmo pino; ","") | M39: =A39&":"&B39&IF(EXACT(B39,UPPER(B39)),"","|lc") | N39: =IFERROR(MATCH(M39,Wires!$W$2:$W$1000,0),IFERROR(MATCH(M39,Wires!$X$2:$X$1000,0),"")) | O39: =IF(N39="","",IF(ISNUMBER(MATCH(M39,Wires!$W$2:$W$1000,0)),"from","to"))
A40: JBOX J1 | B40: K | C40: PWR CAN low | F40: =IF(N40="","",INDEX(Wires!$A$2:$A$1000,N40)) | G40: =IF(N40="","",INDEX(Wires!$C$2:$C$1000,N40)) | H40: =IF(N40="","",IF(O40="from",INDEX(Wires!$F$2:$F$1000,N40)&":"&INDEX(Wires!$G$2:$G$1000,N40),INDEX(Wires!$D$2:$D$1000,N40)&":"&INDEX(Wires!$E$2:$E$1000,N40))) | I40: =IF(N40="","",INDEX(Wires!$H$2:$H$1000,N40)&"") | J40: =IF(N40="","",IF(INDEX(Wires!$I$2:$I$1000,N40)="","",INDEX(Wires!$I$2:$I$1000,N40))) | K40: =COUNTIF(Wires!$W$2:$W$1000,M40)+COUNTIF(Wires!$X$2:$X$1000,M40) | L40: =IF(AND(K40=0,C40<>"",D40<>"NC"),"pino com sinal mas sem fio; ","")&IF(AND(D40="NC",K40>0),"pino NC com fio; ","")&IF(AND(K40>1,ISERROR(MATCH(IFERROR(INDEX(Connectors!$D$2:$D$1000,MATCH(A40,Connectors!$A$2:$A$1000,0)),""),{"SPLICE","STUD"},0))),"vários fios no mesmo pino; ","") | M40: =A40&":"&B40&IF(EXACT(B40,UPPER(B40)),"","|lc") | N40: =IFERROR(MATCH(M40,Wires!$W$2:$W$1000,0),IFERROR(MATCH(M40,Wires!$X$2:$X$1000,0),"")) | O40: =IF(N40="","",IF(ISNUMBER(MATCH(M40,Wires!$W$2:$W$1000,0)),"from","to"))
A41: JBOX J1 | B41: L | C41: PWR CAN High | F41: =IF(N41="","",INDEX(Wires!$A$2:$A$1000,N41)) | G41: =IF(N41="","",INDEX(Wires!$C$2:$C$1000,N41)) | H41: =IF(N41="","",IF(O41="from",INDEX(Wires!$F$2:$F$1000,N41)&":"&INDEX(Wires!$G$2:$G$1000,N41),INDEX(Wires!$D$2:$D$1000,N41)&":"&INDEX(Wires!$E$2:$E$1000,N41))) | I41: =IF(N41="","",INDEX(Wires!$H$2:$H$1000,N41)&"") | J41: =IF(N41="","",IF(INDEX(Wires!$I$2:$I$1000,N41)="","",INDEX(Wires!$I$2:$I$1000,N41))) | K41: =COUNTIF(Wires!$W$2:$W$1000,M41)+COUNTIF(Wires!$X$2:$X$1000,M41) | L41: =IF(AND(K41=0,C41<>"",D41<>"NC"),"pino com sinal mas sem fio; ","")&IF(AND(D41="NC",K41>0),"pino NC com fio; ","")&IF(AND(K41>1,ISERROR(MATCH(IFERROR(INDEX(Connectors!$D$2:$D$1000,MATCH(A41,Connectors!$A$2:$A$1000,0)),""),{"SPLICE","STUD"},0))),"vários fios no mesmo pino; ","") | M41: =A41&":"&B41&IF(EXACT(B41,UPPER(B41)),"","|lc") | N41: =IFERROR(MATCH(M41,Wires!$W$2:$W$1000,0),IFERROR(MATCH(M41,Wires!$X$2:$X$1000,0),"")) | O41: =IF(N41="","",IF(ISNUMBER(MATCH(M41,Wires!$W$2:$W$1000,0)),"from","to"))
A42: JBOX J1 | B42: M | C42: PWR CAN Shield | F42: =IF(N42="","",INDEX(Wires!$A$2:$A$1000,N42)) | G42: =IF(N42="","",INDEX(Wires!$C$2:$C$1000,N42)) | H42: =IF(N42="","",IF(O42="from",INDEX(Wires!$F$2:$F$1000,N42)&":"&INDEX(Wires!$G$2:$G$1000,N42),INDEX(Wires!$D$2:$D$1000,N42)&":"&INDEX(Wires!$E$2:$E$1000,N42))) | I42: =IF(N42="","",INDEX(Wires!$H$2:$H$1000,N42)&"") | J42: =IF(N42="","",IF(INDEX(Wires!$I$2:$I$1000,N42)="","",INDEX(Wires!$I$2:$I$1000,N42))) | K42: =COUNTIF(Wires!$W$2:$W$1000,M42)+COUNTIF(Wires!$X$2:$X$1000,M42) | L42: =IF(AND(K42=0,C42<>"",D42<>"NC"),"pino com sinal mas sem fio; ","")&IF(AND(D42="NC",K42>0),"pino NC com fio; ","")&IF(AND(K42>1,ISERROR(MATCH(IFERROR(INDEX(Connectors!$D$2:$D$1000,MATCH(A42,Connectors!$A$2:$A$1000,0)),""),{"SPLICE","STUD"},0))),"vários fios no mesmo pino; ","") | M42: =A42&":"&B42&IF(EXACT(B42,UPPER(B42)),"","|lc") | N42: =IFERROR(MATCH(M42,Wires!$W$2:$W$1000,0),IFERROR(MATCH(M42,Wires!$X$2:$X$1000,0),"")) | O42: =IF(N42="","",IF(ISNUMBER(MATCH(M42,Wires!$W$2:$W$1000,0)),"from","to"))
A43: JBOX J1 | B43: N | F43: =IF(N43="","",INDEX(Wires!$A$2:$A$1000,N43)) | G43: =IF(N43="","",INDEX(Wires!$C$2:$C$1000,N43)) | H43: =IF(N43="","",IF(O43="from",INDEX(Wires!$F$2:$F$1000,N43)&":"&INDEX(Wires!$G$2:$G$1000,N43),INDEX(Wires!$D$2:$D$1000,N43)&":"&INDEX(Wires!$E$2:$E$1000,N43))) | I43: =IF(N43="","",INDEX(Wires!$H$2:$H$1000,N43)&"") | J43: =IF(N43="","",IF(INDEX(Wires!$I$2:$I$1000,N43)="","",INDEX(Wires!$I$2:$I$1000,N43))) | K43: =COUNTIF(Wires!$W$2:$W$1000,M43)+COUNTIF(Wires!$X$2:$X$1000,M43) | L43: =IF(AND(K43=0,C43<>"",D43<>"NC"),"pino com sinal mas sem fio; ","")&IF(AND(D43="NC",K43>0),"pino NC com fio; ","")&IF(AND(K43>1,ISERROR(MATCH(IFERROR(INDEX(Connectors!$D$2:$D$1000,MATCH(A43,Connectors!$A$2:$A$1000,0)),""),{"SPLICE","STUD"},0))),"vários fios no mesmo pino; ","") | M43: =A43&":"&B43&IF(EXACT(B43,UPPER(B43)),"","|lc") | N43: =IFERROR(MATCH(M43,Wires!$W$2:$W$1000,0),IFERROR(MATCH(M43,Wires!$X$2:$X$1000,0),"")) | O43: =IF(N43="","",IF(ISNUMBER(MATCH(M43,Wires!$W$2:$W$1000,0)),"from","to"))
A44: JBOX J1 | B44: P | C44: Shutdown in | F44: =IF(N44="","",INDEX(Wires!$A$2:$A$1000,N44)) | G44: =IF(N44="","",INDEX(Wires!$C$2:$C$1000,N44)) | H44: =IF(N44="","",IF(O44="from",INDEX(Wires!$F$2:$F$1000,N44)&":"&INDEX(Wires!$G$2:$G$1000,N44),INDEX(Wires!$D$2:$D$1000,N44)&":"&INDEX(Wires!$E$2:$E$1000,N44))) | I44: =IF(N44="","",INDEX(Wires!$H$2:$H$1000,N44)&"") | J44: =IF(N44="","",IF(INDEX(Wires!$I$2:$I$1000,N44)="","",INDEX(Wires!$I$2:$I$1000,N44))) | K44: =COUNTIF(Wires!$W$2:$W$1000,M44)+COUNTIF(Wires!$X$2:$X$1000,M44) | L44: =IF(AND(K44=0,C44<>"",D44<>"NC"),"pino com sinal mas sem fio; ","")&IF(AND(D44="NC",K44>0),"pino NC com fio; ","")&IF(AND(K44>1,ISERROR(MATCH(IFERROR(INDEX(Connectors!$D$2:$D$1000,MATCH(A44,Connectors!$A$2:$A$1000,0)),""),{"SPLICE","STUD"},0))),"vários fios no mesmo pino; ","") | M44: =A44&":"&B44&IF(EXACT(B44,UPPER(B44)),"","|lc") | N44: =IFERROR(MATCH(M44,Wires!$W$2:$W$1000,0),IFERROR(MATCH(M44,Wires!$X$2:$X$1000,0),"")) | O44: =IF(N44="","",IF(ISNUMBER(MATCH(M44,Wires!$W$2:$W$1000,0)),"from","to"))
A45: JBOX J1 | B45: R | C45: Shutdown out | F45: =IF(N45="","",INDEX(Wires!$A$2:$A$1000,N45)) | G45: =IF(N45="","",INDEX(Wires!$C$2:$C$1000,N45)) | H45: =IF(N45="","",IF(O45="from",INDEX(Wires!$F$2:$F$1000,N45)&":"&INDEX(Wires!$G$2:$G$1000,N45),INDEX(Wires!$D$2:$D$1000,N45)&":"&INDEX(Wires!$E$2:$E$1000,N45))) | I45: =IF(N45="","",INDEX(Wires!$H$2:$H$1000,N45)&"") | J45: =IF(N45="","",IF(INDEX(Wires!$I$2:$I$1000,N45)="","",INDEX(Wires!$I$2:$I$1000,N45))) | K45: =COUNTIF(Wires!$W$2:$W$1000,M45)+COUNTIF(Wires!$X$2:$X$1000,M45) | L45: =IF(AND(K45=0,C45<>"",D45<>"NC"),"pino com sinal mas sem fio; ","")&IF(AND(D45="NC",K45>0),"pino NC com fio; ","")&IF(AND(K45>1,ISERROR(MATCH(IFERROR(INDEX(Connectors!$D$2:$D$1000,MATCH(A45,Connectors!$A$2:$A$1000,0)),""),{"SPLICE","STUD"},0))),"vários fios no mesmo pino; ","") | M45: =A45&":"&B45&IF(EXACT(B45,UPPER(B45)),"","|lc") | N45: =IFERROR(MATCH(M45,Wires!$W$2:$W$1000,0),IFERROR(MATCH(M45,Wires!$X$2:$X$1000,0),"")) | O45: =IF(N45="","",IF(ISNUMBER(MATCH(M45,Wires!$W$2:$W$1000,0)),"from","to"))
A46: JBOX J1 | B46: S | C46: BSPD CS Test in | F46: =IF(N46="","",INDEX(Wires!$A$2:$A$1000,N46)) | G46: =IF(N46="","",INDEX(Wires!$C$2:$C$1000,N46)) | H46: =IF(N46="","",IF(O46="from",INDEX(Wires!$F$2:$F$1000,N46)&":"&INDEX(Wires!$G$2:$G$1000,N46),INDEX(Wires!$D$2:$D$1000,N46)&":"&INDEX(Wires!$E$2:$E$1000,N46))) | I46: =IF(N46="","",INDEX(Wires!$H$2:$H$1000,N46)&"") | J46: =IF(N46="","",IF(INDEX(Wires!$I$2:$I$1000,N46)="","",INDEX(Wires!$I$2:$I$1000,N46))) | K46: =COUNTIF(Wires!$W$2:$W$1000,M46)+COUNTIF(Wires!$X$2:$X$1000,M46) | L46: =IF(AND(K46=0,C46<>"",D46<>"NC"),"pino com sinal mas sem fio; ","")&IF(AND(D46="NC",K46>0),"pino NC com fio; ","")&IF(AND(K46>1,ISERROR(MATCH(IFERROR(INDEX(Connectors!$D$2:$D$1000,MATCH(A46,Connectors!$A$2:$A$1000,0)),""),{"SPLICE","STUD"},0))),"vários fios no mesmo pino; ","") | M46: =A46&":"&B46&IF(EXACT(B46,UPPER(B46)),"","|lc") | N46: =IFERROR(MATCH(M46,Wires!$W$2:$W$1000,0),IFERROR(MATCH(M46,Wires!$X$2:$X$1000,0),"")) | O46: =IF(N46="","",IF(ISNUMBER(MATCH(M46,Wires!$W$2:$W$1000,0)),"from","to"))
A47: JBOX J1 | B47: T | C47: BSPD CS Test out | F47: =IF(N47="","",INDEX(Wires!$A$2:$A$1000,N47)) | G47: =IF(N47="","",INDEX(Wires!$C$2:$C$1000,N47)) | H47: =IF(N47="","",IF(O47="from",INDEX(Wires!$F$2:$F$1000,N47)&":"&INDEX(Wires!$G$2:$G$1000,N47),INDEX(Wires!$D$2:$D$1000,N47)&":"&INDEX(Wires!$E$2:$E$1000,N47))) | I47: =IF(N47="","",INDEX(Wires!$H$2:$H$1000,N47)&"") | J47: =IF(N47="","",IF(INDEX(Wires!$I$2:$I$1000,N47)="","",INDEX(Wires!$I$2:$I$1000,N47))) | K47: =COUNTIF(Wires!$W$2:$W$1000,M47)+COUNTIF(Wires!$X$2:$X$1000,M47) | L47: =IF(AND(K47=0,C47<>"",D47<>"NC"),"pino com sinal mas sem fio; ","")&IF(AND(D47="NC",K47>0),"pino NC com fio; ","")&IF(AND(K47>1,ISERROR(MATCH(IFERROR(INDEX(Connectors!$D$2:$D$1000,MATCH(A47,Connectors!$A$2:$A$1000,0)),""),{"SPLICE","STUD"},0))),"vários fios no mesmo pino; ","") | M47: =A47&":"&B47&IF(EXACT(B47,UPPER(B47)),"","|lc") | N47: =IFERROR(MATCH(M47,Wires!$W$2:$W$1000,0),IFERROR(MATCH(M47,Wires!$X$2:$X$1000,0),"")) | O47: =IF(N47="","",IF(ISNUMBER(MATCH(M47,Wires!$W$2:$W$1000,0)),"from","to"))
A48: JBOX J1 | B48: U | C48: FSG Data logger 24 V | F48: =IF(N48="","",INDEX(Wires!$A$2:$A$1000,N48)) | G48: =IF(N48="","",INDEX(Wires!$C$2:$C$1000,N48)) | H48: =IF(N48="","",IF(O48="from",INDEX(Wires!$F$2:$F$1000,N48)&":"&INDEX(Wires!$G$2:$G$1000,N48),INDEX(Wires!$D$2:$D$1000,N48)&":"&INDEX(Wires!$E$2:$E$1000,N48))) | I48: =IF(N48="","",INDEX(Wires!$H$2:$H$1000,N48)&"") | J48: =IF(N48="","",IF(INDEX(Wires!$I$2:$I$1000,N48)="","",INDEX(Wires!$I$2:$I$1000,N48))) | K48: =COUNTIF(Wires!$W$2:$W$1000,M48)+COUNTIF(Wires!$X$2:$X$1000,M48) | L48: =IF(AND(K48=0,C48<>"",D48<>"NC"),"pino com sinal mas sem fio; ","")&IF(AND(D48="NC",K48>0),"pino NC com fio; ","")&IF(AND(K48>1,ISERROR(MATCH(IFERROR(INDEX(Connectors!$D$2:$D$1000,MATCH(A48,Connectors!$A$2:$A$1000,0)),""),{"SPLICE","STUD"},0))),"vários fios no mesmo pino; ","") | M48: =A48&":"&B48&IF(EXACT(B48,UPPER(B48)),"","|lc") | N48: =IFERROR(MATCH(M48,Wires!$W$2:$W$1000,0),IFERROR(MATCH(M48,Wires!$X$2:$X$1000,0),"")) | O48: =IF(N48="","",IF(ISNUMBER(MATCH(M48,Wires!$W$2:$W$1000,0)),"from","to"))
A49: JBOX J1 | B49: V | C49: FSG Data logger GND | F49: =IF(N49="","",INDEX(Wires!$A$2:$A$1000,N49)) | G49: =IF(N49="","",INDEX(Wires!$C$2:$C$1000,N49)) | H49: =IF(N49="","",IF(O49="from",INDEX(Wires!$F$2:$F$1000,N49)&":"&INDEX(Wires!$G$2:$G$1000,N49),INDEX(Wires!$D$2:$D$1000,N49)&":"&INDEX(Wires!$E$2:$E$1000,N49))) | I49: =IF(N49="","",INDEX(Wires!$H$2:$H$1000,N49)&"") | J49: =IF(N49="","",IF(INDEX(Wires!$I$2:$I$1000,N49)="","",INDEX(Wires!$I$2:$I$1000,N49))) | K49: =COUNTIF(Wires!$W$2:$W$1000,M49)+COUNTIF(Wires!$X$2:$X$1000,M49) | L49: =IF(AND(K49=0,C49<>"",D49<>"NC"),"pino com sinal mas sem fio; ","")&IF(AND(D49="NC",K49>0),"pino NC com fio; ","")&IF(AND(K49>1,ISERROR(MATCH(IFERROR(INDEX(Connectors!$D$2:$D$1000,MATCH(A49,Connectors!$A$2:$A$1000,0)),""),{"SPLICE","STUD"},0))),"vários fios no mesmo pino; ","") | M49: =A49&":"&B49&IF(EXACT(B49,UPPER(B49)),"","|lc") | N49: =IFERROR(MATCH(M49,Wires!$W$2:$W$1000,0),IFERROR(MATCH(M49,Wires!$X$2:$X$1000,0),"")) | O49: =IF(N49="","",IF(ISNUMBER(MATCH(M49,Wires!$W$2:$W$1000,0)),"from","to"))
A50: JBOX J1 | B50: W | C50: AD CAN Low | F50: =IF(N50="","",INDEX(Wires!$A$2:$A$1000,N50)) | G50: =IF(N50="","",INDEX(Wires!$C$2:$C$1000,N50)) | H50: =IF(N50="","",IF(O50="from",INDEX(Wires!$F$2:$F$1000,N50)&":"&INDEX(Wires!$G$2:$G$1000,N50),INDEX(Wires!$D$2:$D$1000,N50)&":"&INDEX(Wires!$E$2:$E$1000,N50))) | I50: =IF(N50="","",INDEX(Wires!$H$2:$H$1000,N50)&"") | J50: =IF(N50="","",IF(INDEX(Wires!$I$2:$I$1000,N50)="","",INDEX(Wires!$I$2:$I$1000,N50))) | K50: =COUNTIF(Wires!$W$2:$W$1000,M50)+COUNTIF(Wires!$X$2:$X$1000,M50) | L50: =IF(AND(K50=0,C50<>"",D50<>"NC"),"pino com sinal mas sem fio; ","")&IF(AND(D50="NC",K50>0),"pino NC com fio; ","")&IF(AND(K50>1,ISERROR(MATCH(IFERROR(INDEX(Connectors!$D$2:$D$1000,MATCH(A50,Connectors!$A$2:$A$1000,0)),""),{"SPLICE","STUD"},0))),"vários fios no mesmo pino; ","") | M50: =A50&":"&B50&IF(EXACT(B50,UPPER(B50)),"","|lc") | N50: =IFERROR(MATCH(M50,Wires!$W$2:$W$1000,0),IFERROR(MATCH(M50,Wires!$X$2:$X$1000,0),"")) | O50: =IF(N50="","",IF(ISNUMBER(MATCH(M50,Wires!$W$2:$W$1000,0)),"from","to"))
A51: JBOX J1 | B51: X | C51: AD CAN High | F51: =IF(N51="","",INDEX(Wires!$A$2:$A$1000,N51)) | G51: =IF(N51="","",INDEX(Wires!$C$2:$C$1000,N51)) | H51: =IF(N51="","",IF(O51="from",INDEX(Wires!$F$2:$F$1000,N51)&":"&INDEX(Wires!$G$2:$G$1000,N51),INDEX(Wires!$D$2:$D$1000,N51)&":"&INDEX(Wires!$E$2:$E$1000,N51))) | I51: =IF(N51="","",INDEX(Wires!$H$2:$H$1000,N51)&"") | J51: =IF(N51="","",IF(INDEX(Wires!$I$2:$I$1000,N51)="","",INDEX(Wires!$I$2:$I$1000,N51))) | K51: =COUNTIF(Wires!$W$2:$W$1000,M51)+COUNTIF(Wires!$X$2:$X$1000,M51) | L51: =IF(AND(K51=0,C51<>"",D51<>"NC"),"pino com sinal mas sem fio; ","")&IF(AND(D51="NC",K51>0),"pino NC com fio; ","")&IF(AND(K51>1,ISERROR(MATCH(IFERROR(INDEX(Connectors!$D$2:$D$1000,MATCH(A51,Connectors!$A$2:$A$1000,0)),""),{"SPLICE","STUD"},0))),"vários fios no mesmo pino; ","") | M51: =A51&":"&B51&IF(EXACT(B51,UPPER(B51)),"","|lc") | N51: =IFERROR(MATCH(M51,Wires!$W$2:$W$1000,0),IFERROR(MATCH(M51,Wires!$X$2:$X$1000,0),"")) | O51: =IF(N51="","",IF(ISNUMBER(MATCH(M51,Wires!$W$2:$W$1000,0)),"from","to"))
...

Sheet Parts
A1: pn | B1: manufacturer | C1: type | D1: description | E1: awg_range | F1: source | G1: confirmed | H1: datasheet
A2: MS20W23F-10 | B2: Amphenol Sine RTS (ecomate, circular) | C2: crimp | D2: contacto fêmea tamanho 20, crimp | E2: 20–22 AWG | F2: Notion · LART Central / Electronics / Inventory Management / BOM Management / Connectors Harness (2026-10-22) | G2: N
A3: RTS718N32S03 | B3: Amphenol Sine RTS (ecomate, circular) | C3: ficha | D3: 32 vias · conector principal das caixas: Rasp Box, Data Box, LV Box ×2, Junction Box, Acumulador | F3: Notion · LART Central / Electronics / Inventory Management / BOM Management / Connectors Harness (2026-10-22) | G3: N

Sheet Segments
A1: seg_id | B1: from_node | C1: to_node | D1: length_mm | E1: harness

Sheet Nodes
A1: node | B1: x_m | C1: y_m | D1: z_m | E1: notes

Sheet Issues
A1: id | B1: severity | C1: where | D1: problem | E1: option_a | F1: option_b | G1: applied_here | H1: team_decision | I1: status | J1: n_wires
A2: I-01 | B2: menor | C2: 3 linha(s) | D2: Destino sem pino: TSAL RED J1:1 → destino FUSE 1 sem pino (folha TSAL Red); TSAL RED D2:1 → destino JBOX J1 sem pino (folha TSAL Red); TSAL RED D2:2 → destino JBOX J1 sem pino (folha TSAL Red) | G2: Pino marcado "?" | I2: aberto | J2: =COUNTIF(Wires!$U$2:$U$1000,"*"&A2&"*")
A3: I-02 | B3: info | C3: destinos | D3: 4 conector(es) só aparecem como destino, sem folha própria: AIR-, FUSE 1, GND BOARD, GROUND POINT. | I3: aberto | J3: =COUNTIF(Wires!$U$2:$U$1000,"*"&A3&"*")
A4: I-03 | B4: info | C4: reciprocidade | D4: 2 fio(s) só estão escritos numa das pontas, embora as duas tenham folha: TSAL RED D2:1→JBOX J1:?1, TSAL RED D2:2→JBOX J1:?2 | I4: aberto | J4: =COUNTIF(Wires!$U$2:$U$1000,"*"&A4&"*")
A5: I-04 | B5: info | C5: folhas | D5: Folhas não lidas: Sensors & Actuators (folha sem tabela Conector/Pin — não lida) | I5: aberto | J5: =COUNTIF(Wires!$U$2:$U$1000,"*"&A5&"*")

Sheet Notes
A1: sheet | B1: note

Sheet Lists
A1: colour | B1: nome | C1: uso proposto | E1: csa_mm2 | F1: awg ≈
A2: Cores IEC 60757 | E2: Secção → AWG (equivalência aproximada)
A3: BK | B3: preto | E3: 0.14 | F3: 26
A4: BN | B4: castanho | C4: GND | E4: 0.22 | F4: 24
A5: RD | B5: vermelho | C5: CAN H | E5: 0.35 | F5: 22
A6: OG | B6: laranja | C6: HV (obrigatório) | E6: 0.5 | F6: 20
A7: YE | B7: amarelo | C7: +24 V | E7: 0.75 | F7: 18
A8: GN | B8: verde | C8: CAN carregador H | E8: 1 | F8: 17
A9: BU | B9: azul | C9: SDC / CAN L | E9: 1.5 | F9: 16
A10: VT | B10: violeta | C10: CAN carregador L | E10: 2.5 | F10: 14
A11: GY | B11: cinzento | E11: 4 | F11: 12
A12: WH | B12: branco | C12: sinal | E12: 6 | F12: 10
A13: PK | B13: rosa | E13: 10 | F13: 8
A14: TQ | B14: turquesa | E14: 16 | F14: 6
E15: 25 | F15: 4
E16: 35 | F16: 2
E17: 50 | F17: 1
